<?xml version="1.0" encoding="utf-8"?>

<robot name="mrm" xmlns:xacro="http://www.ros.org/wiki/xacro">

  <link name="dummy"> </link>

  <link
    name="base_link">
    <inertial>
      <origin
        xyz="0.0165249628989607 0.00409986602389259 0.0781788290296329"
        rpy="0 0 0" />
      <mass
        value="167.100405445867" />
      <inertia
        ixx="000.389655431629312"
        ixy="537.317989393359E-06"
        ixz="-278.402379892452E-06"
        iyy="000.464142057314943"
        iyz="685.671608678509E-08"
        izz="000.81767891501105" />
    </inertial>
    <visual>
      <origin
        xyz="0 0 0"
        rpy="0 0 0" />
      <geometry>
        <mesh
          filename="package://mrm_description/meshes/base_link.STL" />
      </geometry>
      <material
        name="">
        <color
          rgba="0.792156862745098 0.819607843137255 0.933333333333333 1" />
      </material>
    </visual>
    <collision>
      <origin
        xyz="0 0 0"
        rpy="0 0 0" />
      <geometry>
        <mesh
          filename="package://mrm_description/meshes/base_link.STL" />
      </geometry>
    </collision>
  </link>

  <joint name="dummy_joint" type="fixed">
     <parent link="dummy"/>
     <child link="base_link"/>
  </joint>

  <link
    name="link_01">
    <inertial>
      <origin
        xyz="0.0672767756765975 2.98471164450476E-10 -2.54315929426596E-10"
        rpy="0 0 0" />
      <mass
        value="019.6260586154462" />
      <inertia
        ixx="725.703453165916E-05"
        ixy="-368.01509681729E-12"
        ixz="249.729356473699E-12"
        iyy="403.260652913686E-05"
        iyz="404.539666739104E-12"
        izz="403.260679465834E-05" />
    </inertial>
    <visual>
      <origin
        xyz="0 0 0"
        rpy="0 0 0" />
      <geometry>
        <mesh
          filename="package://mrm_description/meshes/link_01.STL" />
      </geometry>
      <material
        name="">
        <color
          rgba="0.792156862745098 0.819607843137255 0.933333333333333 1" />
      </material>
    </visual>
    <collision>
      <origin
        xyz="0 0 0"
        rpy="0 0 0" />
      <geometry>
        <mesh
          filename="package://mrm_description/meshes/link_01.STL" />
      </geometry>
    </collision>
  </link>
  <joint
    name="base_link__link_01"
    type="continuous">
    <origin
      xyz="-0.0271913742094736 -0.0470968416584263 0.02885"
      rpy="2.85358761494837 0 -2.0943951023932" />
    <parent
      link="base_link" />
    <child
      link="link_01" />
    <axis
      xyz="-1 0 0" />
    <limit effort="100" velocity="100"/>
    <dynamics damping="0.1" friction="0.1" />
  </joint>
  <link
    name="link_02">
    <inertial>
      <origin
        xyz="0.0203119238637717 1.02704067472814E-10 -1.48791812204507E-10"
        rpy="0 0 0" />
      <mass
        value="018.8138057154393" />
      <inertia
        ixx="721.667925935897E-05"
        ixy="314.461314501011E-12"
        ixz="163.704370735285E-12"
        iyy="395.012859157598E-05"
        iyz="-340.546378650128E-12"
        izz="395.012896092445E-05" />
    </inertial>
    <visual>
      <origin
        xyz="0 0 0"
        rpy="0 0 0" />
      <geometry>
        <mesh
          filename="package://mrm_description/meshes/link_02.STL" />
      </geometry>
      <material
        name="">
        <color
          rgba="0.792156862745098 0.819607843137255 0.933333333333333 1" />
      </material>
    </visual>
    <collision>
      <origin
        xyz="0 0 0"
        rpy="0 0 0" />
      <geometry>
        <mesh
          filename="package://mrm_description/meshes/link_02.STL" />
      </geometry>
    </collision>
  </link>
  <joint
    name="base_link__link_02"
    type="continuous">
    <origin
      xyz="0.101764514288352 0 0.02885"
      rpy="-0.0819857576579163 0 0" />
    <parent
      link="base_link" />
    <child
      link="link_02" />
    <axis
      xyz="1 0 0" />
    <limit effort="100" velocity="100"/>
    <dynamics damping="0.1" friction="0.1" />
  </joint>
  <link
    name="link_03">
    <inertial>
      <origin
        xyz="0.00555996459306347 -7.44617145720383E-11 -3.91775001329364E-10"
        rpy="0 0 0" />
      <mass
        value="018.8138059255539" />
      <inertia
        ixx="721.667937235871E-05"
        ixy="-148.975764619711E-12"
        ixz="-370.604573301297E-12"
        iyy="395.012916802367E-05"
        iyz="-291.006406694619E-12"
        izz="395.012851637099E-05" />
    </inertial>
    <visual>
      <origin
        xyz="0 0 0"
        rpy="0 0 0" />
      <geometry>
        <mesh
          filename="package://mrm_description/meshes/link_03.STL" />
      </geometry>
      <material
        name="">
        <color
          rgba="0.792156862745098 0.819607843137255 0.933333333333333 1" />
      </material>
    </visual>
    <collision>
      <origin
        xyz="0 0 0"
        rpy="0 0 0" />
      <geometry>
        <mesh
          filename="package://mrm_description/meshes/link_03.STL" />
      </geometry>
    </collision>
  </link>
  <joint
    name="base_link__link_03"
    type="continuous">
    <origin
      xyz="-0.0582582368342076 0.10090622615623 0.0288500000000003"
      rpy="-3.13075110136062 0 2.09439510239319" />
    <parent
      link="base_link" />
    <child
      link="link_03" />
    <axis
      xyz="-1 0 0" />
    <limit effort="100" velocity="100"/>
    <dynamics damping="0.1" friction="0.1" />
  </joint>
  <link
    name="link_04">
    <inertial>
      <origin
        xyz="0.0267737977753559 0.0531966120716998 0.0584976172989723"
        rpy="0 0 0" />
      <mass
        value="0.716120012709118" />
      <inertia
        ixx="0.000667568460450479"
        ixy="-7.45811090650663E-06"
        ixz="-2.10836884085224E-06"
        iyy="0.000472984526312464"
        iyz="-3.57398050259442E-05"
        izz="0.000476137167059462" />
    </inertial>
    <visual>
      <origin
        xyz="0 0 0"
        rpy="0 0 0" />
      <geometry>
        <mesh
          filename="package://mrm_description/meshes/link_04.STL" />
      </geometry>
      <material
        name="">
        <color
          rgba="0.501960784313725 0 0 1" />
      </material>
    </visual>
    <collision>
      <origin
        xyz="0 0 0"
        rpy="0 0 0" />
      <geometry>
        <mesh
          filename="package://mrm_description/meshes/link_04.STL" />
      </geometry>
    </collision>
  </link>
  <joint
    name="base_link__link_04"
    type="continuous">
    <origin
      xyz="-0.0211233166152997 0 0.191357999999997"
      rpy="0 0 2.6084606796165" />
    <parent
      link="base_link" />
    <child
      link="link_04" />
    <axis
      xyz="0 0 -1" />
    <limit
      effort="10000"
      velocity="100" />
    <dynamics damping="0.1" friction="0.1" />
    <!--effort="0" lower="-3.1416" upper="3.1416" velocity="3.142"-->
  </joint>
  <link
    name="link_05">
    <inertial>
      <origin
        xyz="0.0640275807561449 -0.110344652616036 -0.037695020814677"
        rpy="0 0 0" />
      <mass
        value="0.58205175682887" />
      <inertia
        ixx="0.00199206554691107"
        ixy="0.00101742299801044"
        ixz="2.48796935775158E-08"
        iyy="0.000806564351270633"
        iyz="-4.44898271406962E-08"
        izz="0.00272396951340294" />
    </inertial>
    <visual>
      <origin
        xyz="0 0 0"
        rpy="0 0 0" />
      <geometry>
        <mesh
          filename="package://mrm_description/meshes/link_05.STL" />
      </geometry>
      <material
        name="">
        <color
          rgba="0.792156862745098 0.819607843137255 0.933333333333333 1" />
      </material>
    </visual>
    <collision>
      <origin
        xyz="0 0 0"
        rpy="0 0 0" />
      <geometry>
        <mesh
          filename="package://mrm_description/meshes/link_05.STL" />
      </geometry>
    </collision>
  </link>
  <joint
    name="link_04__link_05"
    type="continuous">
    <origin
      xyz="-0.00196799999999722 0.0641455492719177 0.0825753987384159"
      rpy="1.5707963267949 -1.3832006673965 1.5707963267949" />
    <parent
      link="link_04" />
    <child
      link="link_05" />
    <axis
      xyz="0 0 -1" />
    <limit
      effort="10000"
      velocity="100" />
    <dynamics damping="0.1" friction="0.1" />
    <!--effort="0" lower="-1.5708" upper="2.6180" velocity="3.142"-->
  </joint>
  <link
    name="link_06">
    <inertial>
      <origin
        xyz="6.94705017183217E-05 -0.0241599694485403 0.0289449615619604"
        rpy="0 0 0" />
      <mass
        value="0.187698685431674" />
      <inertia
        ixx="4.81553745640557E-05"
        ixy="5.12245926199012E-07"
        ixz="2.21204236544749E-06"
        iyy="6.59406536224244E-05"
        iyz="-6.52981287991781E-08"
        izz="6.13486695790917E-05" />
    </inertial>
    <visual>
      <origin
        xyz="0 0 0"
        rpy="0 0 0" />
      <geometry>
        <mesh
          filename="package://mrm_description/meshes/link_06.STL" />
      </geometry>
      <material
        name="">
        <color
          rgba="0.792156862745098 0.819607843137255 0.933333333333333 1" />
      </material>
    </visual>
    <collision>
      <origin
        xyz="0 0 0"
        rpy="0 0 0" />
      <geometry>
        <mesh
          filename="package://mrm_description/meshes/link_06.STL" />
      </geometry>
    </collision>
  </link>
  <joint
    name="link_05__link_06"
    type="continuous">
    <origin
      xyz="0.152500019081648 -0.264137747766138 -0.0287449937659318"
      rpy="0 0 -1.95072116701896" />
    <parent
      link="link_05" />
    <child
      link="link_06" />
    <axis
      xyz="0 0 -1" />
    <limit
      effort="10000"
      velocity="100" />
    <dynamics damping="0.1" friction="0.1" />
    <!--effort="0" lower="-4.1539" upper="1.3788" velocity="3.142"-->
  </joint>
  <link
    name="link_07">
    <inertial>
      <origin
        xyz="-0.00589601954278368 -0.000831155179271126 0.164348992799294"
        rpy="0 0 0" />
      <mass
        value="0.336860625407319" />
      <inertia
        ixx="0.0005666364496686"
        ixy="8.03996409195183E-08"
        ixz="5.68429548646166E-07"
        iyy="0.000527444148945868"
        iyz="-1.36522871148927E-06"
        izz="0.000101696969853834" />
    </inertial>
    <visual>
      <origin
        xyz="0 0 0"
        rpy="0 0 0" />
      <geometry>
        <mesh
          filename="package://mrm_description/meshes/link_07.STL" />
      </geometry>
      <material
        name="">
        <color
          rgba="0.250980392156863 0.250980392156863 0.250980392156863 1" />
      </material>
    </visual>
    <collision>
      <origin
        xyz="0 0 0"
        rpy="0 0 0" />
      <geometry>
        <mesh
          filename="package://mrm_description/meshes/link_07.STL" />
      </geometry>
    </collision>
  </link>
  <joint
    name="link_06__link_07"
    type="continuous">
    <origin
      xyz="-0.0776686808334739 0 0.0366999960447778"
      rpy="1.57079632679489 1.20141276283064 1.57079632679488" />
    <parent
      link="link_06" />
    <child
      link="link_07" />
    <axis
      xyz="0 0 -1" />
    <limit
      effort="10000"
      velocity="100" />
    <dynamics damping="0.1" friction="0.1" />
    <!--effort="0" lower="-2.7925" upper="2.7925" velocity="5.585"-->
  </joint>
  <link
    name="link_08">
    <inertial>
      <origin
        xyz="-0.00106778257608331 -0.00219246401165679 -0.0132750790026302"
        rpy="0 0 0" />
      <mass
        value="0.109812409164527" />
      <inertia
        ixx="1.97227966624028E-05"
        ixy="2.08419633342034E-09"
        ixz="-8.46000709502512E-09"
        iyy="2.10234661938835E-05"
        iyz="-6.00168986211762E-08"
        izz="2.06764169924036E-05" />
    </inertial>
    <visual>
      <origin
        xyz="0 0 0"
        rpy="0 0 0" />
      <geometry>
        <mesh
          filename="package://mrm_description/meshes/link_08.STL" />
      </geometry>
      <material
        name="">
        <color
          rgba="0.250980392156863 0.250980392156863 0.250980392156863 1" />
      </material>
    </visual>
    <collision>
      <origin
        xyz="0 0 0"
        rpy="0 0 0" />
      <geometry>
        <mesh
          filename="package://mrm_description/meshes/link_08.STL" />
      </geometry>
    </collision>
  </link>
  <joint
    name="link_07__link_08"
    type="continuous">
    <origin
      xyz="0.00158364432921804 0 0.300299938443155"
      rpy="3.14159265358979 1.21488546129988 -1.5707963267948" />
    <parent
      link="link_07" />
    <child
      link="link_08" />
    <axis
      xyz="0 1 0" />
    <limit
      effort="10000"
      velocity="100" />
    <dynamics damping="0.1" friction="0.1" />
    <!--effort="0" lower="-1.5708" upper="2.3562" velocity="6.632"-->
  </joint>
  <link
    name="link_09">
    <inertial>
      <origin
        xyz="2.50094408932311E-08 9.75714786743964E-10 0.00914323272922141"
        rpy="0 0 0" />
      <mass
        value="0.0138627440376918" />
      <inertia
        ixx="1.35964557900917E-06"
        ixy="2.89200521540229E-13"
        ixz="-4.69760226794587E-15"
        iyy="1.71572077758348E-06"
        iyz="6.33682293437028E-09"
        izz="2.43318056797383E-06" />
    </inertial>
    <visual>
      <origin
        xyz="0 0 0"
        rpy="0 0 0" />
      <geometry>
        <mesh
          filename="package://mrm_description/meshes/link_09.STL" />
      </geometry>
      <material
        name="">
        <color
          rgba="0.792156862745098 0.819607843137255 0.933333333333333 1" />
      </material>
    </visual>
    <collision>
      <origin
        xyz="0 0 0"
        rpy="0 0 0" />
      <geometry>
        <mesh
          filename="package://mrm_description/meshes/link_09.STL" />
      </geometry>
    </collision>
  </link>
  <joint
    name="link_08__link_09"
    type="continuous">
    <origin
      xyz="0 0 0.0202499693561532"
      rpy="0 0 -0.605380923516401" />
    <parent
      link="link_08" />
    <child
      link="link_09" />
    <axis
      xyz="0 0 1" />
    <limit
      effort="10000"
      velocity="100" />
    <dynamics damping="0.1" friction="0.1" />
    <!--effort="0" lower="-3.4907" upper="3.4907" velocity="8.029"-->
  </joint>

  <transmission name="trans_base_link__link_01">
        <type>transmission_interface/SimpleTransmission</type>
        <joint name="base_link__link_01">
                <hardwareInterface>hardware_interface/VelocityJointInterface</hardwareInterface>
        </joint>
        <actuator name="motor_base_link__link_01">
                <hardwareInterface>hardware_interface/VelocityJointInterface</hardwareInterface>
                <mechanicalReduction>1</mechanicalReduction>
        </actuator>
  </transmission>
  <transmission name="trans_base_link__link_02">
        <type>transmission_interface/SimpleTransmission</type>
        <joint name="base_link__link_02">
                <hardwareInterface>hardware_interface/VelocityJointInterface</hardwareInterface>
        </joint>
        <actuator name="motor_base_link__link_02">
                <hardwareInterface>hardware_interface/VelocityJointInterface</hardwareInterface>
                <mechanicalReduction>1</mechanicalReduction>
        </actuator>
  </transmission>
  <transmission name="trans_base_link__link_03">
        <type>transmission_interface/SimpleTransmission</type>
        <joint name="base_link__link_03">
                <hardwareInterface>hardware_interface/VelocityJointInterface</hardwareInterface>
        </joint>
        <actuator name="motor_base_link__link_03">
                <hardwareInterface>hardware_interface/VelocityJointInterface</hardwareInterface>
                <mechanicalReduction>1</mechanicalReduction>
        </actuator>
  </transmission>

  <transmission name="trans_base_link__link_04">
        <type>transmission_interface/SimpleTransmission</type>
        <joint name="base_link__link_04">
                <hardwareInterface>hardware_interface/PositionJointInterface</hardwareInterface>
        </joint>
        <actuator name="motor_base_link__link_04">
                <hardwareInterface>hardware_interface/PositionJointInterface</hardwareInterface>
                <mechanicalReduction>1</mechanicalReduction>
        </actuator>
  </transmission>
  <transmission name="trans_link_04__link_05">
        <type>transmission_interface/SimpleTransmission</type>
        <joint name="link_04__link_05">
                <hardwareInterface>hardware_interface/PositionJointInterface</hardwareInterface>
        </joint>
        <actuator name="motor_link_04__link_05">
                <hardwareInterface>hardware_interface/PositionJointInterface</hardwareInterface>
                <mechanicalReduction>1</mechanicalReduction>
        </actuator>
  </transmission>
  <transmission name="trans_link_05__link_06">
        <type>transmission_interface/SimpleTransmission</type>
        <joint name="link_05__link_06">
                <hardwareInterface>hardware_interface/PositionJointInterface</hardwareInterface>
        </joint>
        <actuator name="motor_link_05__link_06">
                <hardwareInterface>hardware_interface/PositionJointInterface</hardwareInterface>
                <mechanicalReduction>1</mechanicalReduction>
        </actuator>
  </transmission>
  <transmission name="trans_link_06__link_07">
        <type>transmission_interface/SimpleTransmission</type>
        <joint name="link_06__link_07">
                <hardwareInterface>hardware_interface/PositionJointInterface</hardwareInterface>
        </joint>
        <actuator name="motor_link_06__link_07">
                <hardwareInterface>hardware_interface/PositionJointInterface</hardwareInterface>
                <mechanicalReduction>1</mechanicalReduction>
        </actuator>
  </transmission>
  <transmission name="trans_link_07__link_08">
        <type>transmission_interface/SimpleTransmission</type>
        <joint name="link_07__link_08">
                <hardwareInterface>hardware_interface/PositionJointInterface</hardwareInterface>
        </joint>
        <actuator name="motor_link_07__link_08">
                <hardwareInterface>hardware_interface/PositionJointInterface</hardwareInterface>
                <mechanicalReduction>1</mechanicalReduction>
        </actuator>
  </transmission>
  <transmission name="trans_link_08__link_09">
        <type>transmission_interface/SimpleTransmission</type>
        <joint name="link_08__link_09">
                <hardwareInterface>hardware_interface/PositionJointInterface</hardwareInterface>
        </joint>
        <actuator name="motor_link_08__link_09">
                <hardwareInterface>hardware_interface/PositionJointInterface</hardwareInterface>
                <mechanicalReduction>1</mechanicalReduction>
        </actuator>
  </transmission>

  <gazebo>
    <plugin name="gazebo_ros_control" filename="libgazebo_ros_control.so">
      <robotSimType>gazebo_ros_control/DefaultRobotHWSim</robotSimType>
      <legacyModeNS>true</legacyModeNS>
    </plugin>
  </gazebo>
  <gazebo>
    <plugin name="object_controller" filename="libgazebo_ros_planar_move.so">
      <commandTopic>cmd_vel</commandTopic>
      <odometryTopic>odom</odometryTopic>
      <odometryFrame>odom</odometryFrame>
      <odometryRate>20.0</odometryRate>
      <robotBaseFrame>dummy</robotBaseFrame>
    </plugin>
  </gazebo>

</robot>
